Workbook
Name _GoBack: 'الطاقة الاستيعابية'!#REF!

Sheet دليل الملف

Sheet مؤشرات المجمع
A1: المرحلة | B1: عدد الطلاب | C1: حساب الهيئة الإدارية بالنسبة للطلاب Students Administrative Staff Ratio SAR | D1: حساب الهيئة التعليمية بالنسبة للطلاب Students Teaching Ratio STR | E1: حساب الخدمات المساندة بالنسبة للطلاب Students Support Services Ratio SSR | F1: حساب طاقم المجمع بالنسبة للطلاب Students Everyone Ratio SER
C2: 75 | D2: 15/16 | E2: 100 | F2: 10
A3: تمهيدي | B3: ='إحصاء الطلاب'!I6 -> 43 | C3: =B3/0.5 -> 86 | D3: =B3/المعلمات!J35 -> 21.5 | E3: =B3/('الإحصاء العام للمجمع'!H8+'الإحصاء العام للمجمع'!J8) -> 43 | F3: =B3/'الإحصاء العام للمجمع'!K8 -> 10.75
A4: ابتدائي بنات | B4: ='إحصاء الطلاب'!I17 -> 112 | C4: =B4/('اداريات دار القلم'!F32) -> 56 | D4: =B4/المعلمات!J36 -> 12.444444 | E4: =B4/('الإحصاء العام للمجمع'!H10+'الإحصاء العام للمجمع'!J10) -> 56 | F4: =B4/'الإحصاء العام للمجمع'!K10 -> 9.3333333
A5: ابتدائي بنين | B5: ='إحصاء الطلاب'!I24 -> 273 | C5: =B5/('اداريين دار القلم'!F26) -> 91 | D5: =B5/(المعلمين!H66+المعلمين!I66) -> 15.166667 | E5: =B5/('الإحصاء العام للمجمع'!H9+'الإحصاء العام للمجمع'!J9) -> 91 | F5: =B5/'الإحصاء العام للمجمع'!K9 -> 11.375
A6: متوسط بنين | B6: ='إحصاء الطلاب'!I28 -> 204 | C6: =B6/('اداريين دار القلم'!F27) -> 102 | D6: =B6/(المعلمين!H67+المعلمين!I67) -> 17 | E6: =B6/('الإحصاء العام للمجمع'!H11+'الإحصاء العام للمجمع'!J11) -> #DIV/0! | F6: =B6/'الإحصاء العام للمجمع'!K11 -> 13.6
A7: متوسط بنات | B7: ='إحصاء الطلاب'!I32 -> 48 | C7: =B7/('اداريات دار القلم'!F33) -> 24 | D7: =B7/(المعلمات!J37) -> 12 | E7: =B7/('الإحصاء العام للمجمع'!H12+'الإحصاء العام للمجمع'!J12) -> #DIV/0! | F7: =B7/'الإحصاء العام للمجمع'!K12 -> 9.6
A8: ثانوي بنين | B8: =('إحصاء الطلاب'!I43)-('إحصاء الطلاب'!I34+'إحصاء الطلاب'!I36) -> 610 | C8: =B8/('اداريين دار القلم'!F28) -> 101.66667 | D8: =B8/(المعلمين!H68+المعلمين!I68) -> 22.592593 | E8: =B8/('الإحصاء العام للمجمع'!H13+'الإحصاء العام للمجمع'!J13) -> 203.33333 | F8: =B8/'الإحصاء العام للمجمع'!K13 -> 16.944444
A9: ثانوي بنات | B9: ='إحصاء الطلاب'!I53 -> 189 | C9: =B9/('اداريات دار القلم'!F34) -> 47.25 | D9: =B9/(المعلمات!J38) -> 18.9 | E9: =B9/('الإحصاء العام للمجمع'!H14+'الإحصاء العام للمجمع'!J14) -> #DIV/0! | F9: =B9/'الإحصاء العام للمجمع'!K14 -> 12.6
A10: مجمع دار القلم | B10: =SUM(B3:B9) -> 1479 | C10: =B10/('اداريين دار القلم'!F29+'اداريات دار القلم'!F35) -> 77.842105 | D10: =B10/(المعلمين!H70+المعلمات!J39) -> 18.036585 | E10: =B10/'الإحصاء العام للمجمع'!F25 -> 147.9 | F10: ='الإحصاء العام للمجمع'!K25 -> 121

Sheet إحصاء الطلاب
A1: احصائية الطلاب والفصول والجنسية
A2: المرحلة | B2: الجنس | C2: الصف | E2: عدد الفصول | F2: تربية خاصة | G2: سعودي | H2: غير سعودي | I2: المجموع | J2: الحصص حسب الخطة | K2: عدد الحصص بالمرحلة | L2: عدد المعلمين | M2: معدل توزيع الحصص | N2: المقاعد الشاغرة
A3: تمهيدي | B3: بنات | C3: م1 | E3: 1 | G3: 5 | H3: 1 | I3: =SUM(G3:H3) -> 6 | N3: =(E3*25)-(F3+G3+H3) -> 19
C4: م2 | E4: 1 | G4: 16 | H4: 0 | I4: =SUM(G4:H4) -> 16 | N4: =(E4*25)-(F4+G4+H4) -> 9
C5: م3 | E5: 1 | G5: 18 | H5: 3 | I5: =SUM(G5:H5) -> 21 | N5: =(E5*25)-(F5+G5+H5) -> 4
A6: مجموع مرحلة التمهيدي | E6: =SUM(E3:E5) -> 3 | F6: =SUM(F3:F5) -> 0 | G6: =SUM(G3:G5) -> 39 | H6: =SUM(H3:H5) -> 4 | I6: =SUM(I3:I5) -> 43 | J6: 0 | K6: 0 | L6: 2 | M6: 0 | N6: =(E6*25)-(F6+G6+H6) -> 32
A7: ابتدائي | B7: بنات | C7: الأول | D7: بنات | E7: 1 | G7: 11 | I7: =SUM(G7:H8) -> 11 | N7: =(E7*25)-(F7+G7+H7) -> 14
D8: بنين | E8: 0 | G8: 0 | H8: 0 | N8: =(E8*25)-(F8+G8+H8) -> 0
C9: الثاني | D9: بنات | E9: 1 | G9: 9 | H9: 8 | I9: =SUM(G9:H10) -> 17 | N9: =(E9*25)-(F9+G9+H9) -> 8
D10: بنين | E10: 0 | G10: 0 | H10: 0 | N10: =(E10*25)-(F10+G10+H10) -> 0
C11: الثالث | D11: بنات | E11: 1 | G11: 24 | H11: 5 | I11: =SUM(G11:H12) -> 37 | N11: =(E11*25)-(F11+G11+H11) -> -4
D12: بنين | E12: 1 | G12: 6 | H12: 2 | N12: =(E12*25)-(F12+G12+H12) -> 17
C13: الرابع | D13: بنات | E13: 1 | G13: 18 | H13: 4 | I13: =SUM(G13:H14) -> 22 | N13: =(E13*25)-(F13+G13+H13) -> 3
D14: بنين | E14: 0 | G14: 0 | H14: 0 | N14: =(E14*25)-(F14+G14+H14) -> 0
C15: الخامس | E15: 1 | G15: 12 | H15: 2 | I15: =SUM(G15:H15) -> 14 | N15: =(E15*25)-(F15+G15+H15) -> 11
C16: السادس | E16: 1 | G16: 9 | H16: 2 | I16: =SUM(G16:H16) -> 11 | N16: =(E16*25)-(F16+G16+H16) -> 14
B17: مجموع المرحلة الابتدائية بنات | E17: =SUM(E7:E16) -> 7 | F17: =SUM(F7:F16) -> 0 | G17: =SUM(G7:G16) -> 89 | H17: =SUM(H7:H16) -> 23 | I17: =SUM(I7:I16) -> 112 | J17: 33 | K17: =E17*J17 -> 231 | L17: 10 | M17: =K17/L17 -> 23.1 | N17: =(E17*25)-(F17+G17+H17) -> 63
B18: بنين | C18: الأول | E18: 2 | F18: 0 | G18: 39 | H18: 5 | I18: =SUM(F18:H18) -> 44 | N18: =(E18*25)-(F18+G18+H18) -> 6
C19: الثاني | E19: 2 | F19: 0 | G19: 40 | H19: 2 | I19: =SUM(F19:H19) -> 42 | N19: =(E19*25)-(F19+G19+H19) -> 8
C20: الثالث | E20: 2 | F20: 0 | G20: 33 | H20: 3 | I20: =SUM(F20:H20) -> 36 | N20: =(E20*25)-(F20+G20+H20) -> 14
C21: الرابع | E21: 3 | F21: 0 | G21: 52 | H21: 9 | I21: =SUM(F21:H21) -> 61 | N21: =(E21*25)-(F21+G21+H21) -> 14
C22: الخامس | E22: 2 | F22: 0 | G22: 47 | H22: 5 | I22: =SUM(F22:H22) -> 52 | N22: =(E22*25)-(F22+G22+H22) -> -2
C23: السادس | E23: 2 | F23: 0 | G23: 31 | H23: 7 | I23: =SUM(F23:H23) -> 38 | N23: =(E23*25)-(F23+G23+H23) -> 12
B24: مجموع المرحلة الابتدائية بنين | E24: =SUM(E18:E23) -> 13 | F24: =SUM(F18:F23) -> 0 | G24: =SUM(G18:G23) -> 242 | H24: =SUM(H18:H23) -> 31 | I24: =SUM(I18:I23) -> 273 | J24: 33 | K24: =E24*J24 -> 429 | L24: 18 | M24: =K24/L24 -> 23.833333 | N24: =(E24*25)-(F24+G24+H24) -> 52
A25: متوسط | B25: بنين | C25: الأول | E25: 3 | F25: 0 | G25: 61 | H25: 8 | I25: =SUM(F25:H25) -> 69 | N25: =(E25*25)-(F25+G25+H25) -> 6
C26: الثاني | E26: 3 | F26: 0 | G26: 61 | H26: 6 | I26: =SUM(F26:H26) -> 67 | N26: =(E26*25)-(F26+G26+H26) -> 8
C27: الثالث | E27: 3 | F27: 0 | G27: 56 | H27: 12 | I27: =SUM(F27:H27) -> 68 | N27: =(E27*25)-(F27+G27+H27) -> 7
B28: مجموع متوسط بنين | E28: =SUM(E25:E27) -> 9 | F28: =SUM(F25:F27) -> 0 | G28: =SUM(G25:G27) -> 178 | H28: =SUM(H25:H27) -> 26 | I28: =SUM(I25:I27) -> 204 | J28: 35 | K28: =E28*J28 -> 315 | L28: 13 | M28: =K28/L28 -> 24.230769 | N28: =(E28*25)-(F28+G28+H28) -> 21
B29: بنات | C29: الأول | E29: 1 | G29: 10 | H29: 4 | I29: =SUM(F29:H29) -> 14 | N29: =(E29*25)-(F29+G29+H29) -> 11
C30: الثاني | E30: 1 | G30: 19 | H30: 0 | I30: =SUM(F30:H30) -> 19 | N30: =(E30*25)-(F30+G30+H30) -> 6
C31: الثالث | E31: 1 | G31: 9 | H31: 6 | I31: =SUM(F31:H31) -> 15 | N31: =(E31*25)-(F31+G31+H31) -> 10
B32: مجموع متوسط بنات | E32: =SUM(E29:E31) -> 3 | F32: =SUM(F29:F31) -> 0 | G32: =SUM(G29:G31) -> 38 | H32: =SUM(H29:H31) -> 10 | I32: =SUM(I29:I31) -> 48 | J32: 35 | K32: =E32*J32 -> 105 | L32: 4 | M32: =K32/L32 -> 26.25 | N32: =(E32*25)-(F32+G32+H32) -> 27
A33: ثانوي | B33: بنين | C33: الأول | D33: مسارات | E33: 6 | F33: 0 | G33: 133 | H33: 37 | I33: =SUM(F33:H33) -> 170 | J33: =I33+I34 -> 203 | N33: =(E33*25)-(F33+G33+H33) -> -20
D34: نون | E34: 2 | F34: 0 | G34: 33 | H34: 0 | I34: =SUM(F34:H34) -> 33 | N34: =(E34*25)-(F34+G34+H34) -> 17
C35: الثاني | D35: عام | E35: 7 | F35: 0 | G35: 176 | H35: 27 | I35: =SUM(F35:H35) -> 203 | J35: =I35+I36+I37+I38 -> 224 | N35: =(E35*25)-(F35+G35+H35) -> -28
D36: نون | E36: 1 | F36: 0 | G36: 21 | H36: 0 | I36: =SUM(F36:H36) -> 21 | N36: =(E36*25)-(F36+G36+H36) -> 4
D37: صحة | I37: =SUM(F37:H37) -> 0 | N37: =(E37*25)-(F37+G37+H37) -> 0
D38: ادارة | I38: =SUM(F38:H38) -> 0 | N38: =(E38*25)-(F38+G38+H38) -> 0
C39: الثالث | D39: عام | E39: 7 | F39: 1 | G39: 197 | H39: 39 | I39: =SUM(F39:H39) -> 237 | J39: =I39+I40+I41+I42 -> 237 | N39: =(E39*25)-(F39+G39+H39) -> -62
D40: حاسب | I40: =SUM(F40:H40) -> 0 | N40: =(E40*25)-(F40+G40+H40) -> 0
...

Sheet المعلمين
A1: عدد المعلمين | B1: بيانات المعلمين ( جميع المراحل )
B3: م | C3: اسم الموظف رباعي | D3: رقم الهوية | E3: الجنسية | F3: رقم الجوال | G3: الإيميل | H3: المؤهل | I3: التخصص | J3: مادة التدريس | K3: المرحلة | L3: نصاب المعلم | M3: الرخصة المهنية | N3: كلاسيرا | O3: ملاحظات
A4: 1 | B4: 122 | C4: محمود محمد عبدالحسيب | D4: 2422265567 | E4: مصري | F4: 560294799 | G4: M.Abdelhaseeb@altanmiyah.edu.sa | H4: ليسانس اداب | I4: لغة عربية | J4: معلم صف | K4: ابتدائي | L4: 24 | M4: 0
A5: 2 | B5: 70 | C5: العفيفي عبدالجواد محمد | D5: 2296977628 | E5: مصري | F5: 567704204 | G5: 70@altanmiyah.edu.sa | H5: ليسانس ازهر | I5: أصول دين ودعوة | J5: معلم صف | K5: ابتدائي | L5: 24 | M5: 0 | U5: ممارس
A6: 3 | B6: 68 | C6: حسن عزالدين حسن مبروك | D6: 2295722868 | E6: مصري | F6: 597772798 | G6: H.Mabrouk@altanmiyah.edu.sa | H6: ليسانس اداب وتربية | I6: لغة عربية | J6: معلم صف | K6: ابتدائي | L6: 24 | M6: 1 | U6: متقدم
A7: 4 | B7: 3067 | C7: محمد ابراهيم عبد اللطيف السيد | D7: 2555223862 | E7: مصري | F7: 501456751 | G7: 3067@altanmiyah.edu.sa | H7: ليسانس اداب وتربية | I7: لغة عربية | J7: لغة عربية | K7: ابتدائي | L7: 24 | M7: 0 | U7: خبير
A8: 5 | B8: 111 | C8: عبدالعزيز محمود يونس | D8: 2314377397 | E8: مصري | F8: 598811372 | G8: A.Younis@altanmiyah.edu.sa | H8: ليسانس ازهر | I8: شريعة اسلامية | J8: معلم صف | K8: ابتدائي | L8: 24 | M8: 0 | U8: محترف
A9: 6 | B9: 28 | C9: محمد السيد كامل الغباشي | D9: 2422497111 | E9: مصري | F9: 581673532 | G9: M.Alghobashi@altanmiyah.edu.sa | H9: ليسانس اداب وتربية | I9: لغة عربية | J9: لغة عربية | K9: ابتدائي | L9: 25 | M9: 1
A10: 7 | B10: 2608 | C10: سلمان بن حمد الفراج | D10: 1103049928 | E10: سعودي | F10: 538394028 | G10: S.Alfarraj@altanmiyah.edu.sa | H10: بكالوريوس | I10: شريعة اسلامية | J10: اسلاميات | K10: ابتدائي | L10: 24 | M10: 1
A11: 8 | B11: 44 | C11: أمير ابراهيم جلال عبدالله | D11: 2320558105 | E11: مصري | F11: 561584133 | G11: ameerjalal@altanmiyah.edu.sa | H11: بكالوريوس علوم | I11: رياضيات وحاسب | J11: مهارات رقمية | K11: ابتدائي | L11: 24 | M11: 1
A12: 9 | B12: 26 | C12: طارق عبد الظاهر بيومي | D12: 2422170593 | E12: مصري | F12: 562987348 | G12: T.Ahmed@altanmiyah.edu.sa | H12: بكالوريوس علوم وتربية | I12: رياضيات | J12: رياضيات | K12: ابتدائي | L12: 24 | M12: 0
A13: 10 | B13: 3844 | C13: عمرو محمد عبدالمقصود غراب | D13: 2581564552 | E13: مصري | F13: 530143943 | G13: 3844@altanmiyah.edu.sa | H13: بكالوريوس علوم وتربية | I13: رياضيات | J13: رياضيات | K13: ابتدائي | L13: 24 | M13: 0
A14: 11 | B14: 72 | C14: ربيع عوض عبد الموجود خليفة | D14: 2396262137 | E14: مصري | F14: 541948873 | G14: 72@altanmiyah.edu.sa | H14: ليسانس اداب وتربية | I14: لغة انجليزية | J14: لغة انجليزية | K14: ابتدائي | L14: 24 | M14: 1
A15: 12 | B15: 27 | C15: رامي محمد يسن معروف العمري | D15: 2422462180 | E15: مصري | F15: 562205859 | G15: R.Maarouf@altanmiyah.edu.sa | H15: بكالوريوس تربية نوعية | I15: تربية فنية | J15: تربية فنية | K15: ابتدائي | L15: 24 | M15: 0
A16: 13 | B16: 98 | C16: محمود رضا ابو المكارم وحش | D16: 2396261717 | E16: مصري | F16: 599536762 | G16: 98@altanmiyah.edu.sa | H16: بكالوريوس تربية رياضية | I16: تربية رياضية | J16: تربية بدنية | K16: ابتدائي | L16: 24 | M16: 1
A17: 14 | B17: 3939 | C17: أيمن محمد علي مصباح | D17: 2581572480 | E17: مصري | F17: 542588417 | G17: 3939@altanmiyah.edu.sa | H17: بكالوريوس علوم وتربية | I17: علوم وتربية | J17: علوم | K17: ابتدائي | L17: 24 | M17: 0
A18: 15 | B18: 96 | C18: مصطفى إبراهيم عبدالتواب | D18: 2382247068 | E18: مصري | F18: 552420543 | G18: m.abdulmawli@altanmiyah.edu.sa | H18: بكالوريوس علوم وتربية | I18: علوم | J18: علوم | K18: ابتدائي | L18: 24 | M18: 1
A19: 16 | B19: 3842 | C19: وليد محمد صالح الصده | D19: 2581564362 | E19: مصري | F19: 537937126 | G19: 3842@altanmiyah.edu.sa | H19: بكالوريوس | I19: رياضيات | J19: رياضيات | K19: ابتدائي | L19: 24 | M19: 0
A20: 17 | B20: 3072 | C20: مصطفى فتحى سيد احمد | D20: 2555225339 | E20: مصري | F20: 570338992 | G20: 3072@ALTANMIYAH.EDU.SA | H20: ليسانس اداب وتربية | I20: لغة انجليزية | J20: لغة انجليزية | K20: ابتدائي | L20: 12 | M20: 1
A21: 18 | B21: 4811 | C21: احمد حسنين عبداللطيف الفراج | D21: 2614676217 | E21: مصري | F21: 540740832 | G21: 4811@altanmiyah.edu.sa | H21: ليسانس اداب وتربية | I21: لغة انجليزية | J21: لغة انجليزية | K21: ابتدائي | L21: 24 | M21: 0
A22: 1 | B22: 3460 | C22: سليمان الصادق الخضر | D22: 2163488170 | E22: سوداني | F22: 567326335 | G22: 3460@altanmiyah.edu.sa | H22: ليسانس اداب وتربية | I22: لغة انجليزية | J22: لغة انجليزية | K22: متوسط | L22: 24 | M22: 0
A23: 2 | B23: 3958 | C23: أحمد محمد الصوفي أحمد | D23: جديد | E23: مصري | F23: 500520431 | G23: 3958@altanmiyah.edu.sa | H23: ليسانس اداب وتربية | I23: لغة عربية | J23: لغة عربية | K23: متوسط | L23: 26 | M23: 0
A24: 3
A25: 4 | B25: 81 | C25: حسن محمد حسن السيد | D25: 2382315600 | E25: مصري | F25: 541567650 | G25: H.Alsayed@altanmiyah.edu.sa | H25: بكالوريوس علوم وتربية | I25: رياضيات | J25: رياضيات | K25: متوسط | L25: 30 | M25: 1
A26: 5 | B26: 151 | C26: محمد محمود العشماوى متولى | D26: 2312390996 | E26: مصري | F26: 597274959 | H26: بكالوريوس علوم وتربية | I26: علم ارض | J26: علوم | K26: متوسط | L26: 27 | M26: 0
A27: 6 | B27: 76 | C27: ماهر مساعد سعد الحربي | D27: 1106119926 | E27: سعودي | F27: 559012194 | G27: 76@altanmiyah.edu.sa | H27: بكالوريوس | I27: رياضيات | J27: رياضيات | K27: متوسط | L27: 24 | M27: 1
A28: 7 | B28: 3070 | C28: فارس مصباح علي عبدالرحمن | D28: 2555220850 | E28: مصري | F28: 553871702 | G28: 3070@altanmiyah.edu.sa | H28: بكالوريوس علوم وتربية | I28: كيمياء | J28: كيمياء | K28: متوسط | L28: 24 | M28: 0
A29: 8 | B29: 69 | C29: محمد محمد سمير الدالي | D29: 2312390483 | E29: مصري | F29: 559462197 | G29: M.Samir@altanmiyah.edu.sa | H29: ليسانس اداب وتربية | I29: لغة عربية | J29: لغة عربية | K29: متوسط | L29: 27 | M29: 1
A30: 9 | B30: 33 | C30: محمود صابر محمود سعيد | D30: 2265322129 | E30: مصري | F30: 559462197 | G30: M.Saber@altanmiyah.edu.sa | H30: بكالوريوس تربية نوعية | I30: تربية نوعية | J30: تربية فنية | K30: متوسط | L30: 27 | M30: 0
A31: 10 | B31: 3843 | C31: محمود جمعة مصري | D31: 2581557127 | E31: مصري | F31: 561332454 | G31: 3843@altanmiyah.edu.sa | H31: بكالوريوس تربية نوعية | I31: تكنولجيا معلومات | J31: مهارات رقمية | K31: متوسط | L31: 25 | M31: 0
A32: 11 | B32: 3079 | C32: محمد سيد عبدالجواد عبدالله | D32: 2554811279 | E32: مصري | F32: 557940130 | G32: 3079@altanmiyah.edu.sa | H32: ليسانس اداب وتربية | I32: لغة انجليزية | J32: لغة انجليزية | K32: متوسط | L32: 24 | M32: 0
A33: 12 | C33: صقر | E33: سعودي | K33: متوسط | L33: 24 | M33: 0
A34: 13 | B34: 57 | C34: حسين علي محمد عبدالحميد | D34: 2459416059 | E34: مصري | F34: 590775476 | G34: H.Awaida@altanmiyah.edu.sa | H34: بكالوريوس تربية رياضية | I34: تربية رياضية | J34: بدنية | K34: متوسط | L34: 13 | M34: 0
A35: 1 | B35: 160 | C35: سلمان محمد عبدالرحمن سالمان | D35: 2442472367 | E35: مصري | F35: 545793386 | G35: S.Salman@altanmiyah.edu.sa | H35: بكالوريوس علوم وتربية | I35: فيزياء وكيمياء | J35: فيزياء | K35: ثانوي | L35: 28 | M35: 0
A36: 2 | B36: 158 | C36: أحمد طاهر عبد المعطي بهيدي | D36: 2422266318 | E36: مصري | F36: 560288340 | G36: A.Bahidi@altanmiyah.edu.sa | H36: بكالوريوس علوم وتربية | I36: فيزياء وكيمياء | J36: كيمياء | K36: ثانوي | L36: 27 | M36: 1
A37: 3 | B37: 3069 | C37: محمد على سالم سليم | D37: 2555224332 | E37: مصري | F37: 560288340 | G37: 3069@altanmiyah.edu.sa | H37: بكالوريوس علوم وتربية | I37: رياضيات | J37: رياضيات | K37: ثانوي | L37: 28 | M37: 0
A38: 4 | B38: 3577 | C38: عبدالعزيز صالح محمد الربيعان | D38: 1100905122 | E38: سعودي | F38: 554808786 | G38: 3577@altanmiyah.edu.sa | H38: بكالوريوس | I38: لغه عربيه | J38: اجتماعيات | K38: ثانوي | L38: 24 | M38: 0
A39: 5 | C39: ريان | E39: سعودي | J39: اسلاميات
A40: 6 | C40: إبراهيم شبكة | D40: 2107240462 | E40: مصري | F40: 508901528 | G40: i.shabka@altanmiyah.edu.sa | H40: ليسانس اداب وتربية | I40: لغة انجليزية | J40: لغة انجليزية | K40: ثانوي | L40: 24 | M40: 0
A41: 7 | B41: 667 | C41: حسن جوده حسن محمد | D41: 24441761695 | E41: مصري | F41: 592141776 | G41: h.joudah@altanmiyah.edu.sa | H41: بكالوريوس علوم وتربية | I41: فيزياء وكيمياء | J41: فيزياء | K41: ثانوي | L41: 24 | M41: 0
...

Sheet المعلمات
B1: بيانات المعلمات ( جميع المراحل )
B3: م | C3: اسم الموظفة رباعي | D3: رقم الهوية | E3: الجنسية | F3: رقم الجوال | G3: الإيميل | H3: المؤهل | I3: التخصص | J3: مادة التدريس | K3: المرحلة | L3: الرخصة المهنية | M3: ملاحظات
A4: 1 | B4: 195 | C4: أثير محمد بن سعد الحربي | D4: 1101391603 | E4: سعودية | F4: 535375812 | G4: atheer.alharbi@altanmiyah.edu.sa | H4: بكالوريوس | I4: رياض أطفال | J4: رياض أطفال | K4: تمهيدي | L4: 1
A5: 2 | B5: 201 | C5: ساره فهد عبدالله العجمي | D5: 1070000169 | E5: سعودية | F5: 551391313 | G5: s.alajmi@altanmiyah.edu.sa | H5: بكالوريوس | I5: رياض أطفال | J5: رياض أطفال | K5: تمهيدي | L5: 1
A6: 1 | B6: 277 | C6: منى مقبل بن عبد العزيز الخلف | D6: 1030800088 | E6: سعودية | F6: 555994993 | G6: M.Alkhalaf@altanmiyah.edu.sa | H6: بكالوريوس | I6: احياء | J6: علوم | K6: ابتدائي | L6: 1
A7: 2 | B7: 4411 | C7: ناهد يحى محسن بعزفي | D7: 1096733116 | E7: سعودية | F7: 506776366 | G7: 4411@altanmiyah.edu.sa | H7: بكالوريوس | I7: لغة عربية | J7: لغة عربية | K7: ابتدائي | L7: 1 | M7: اسرية
A8: 3 | B8: 3979 | C8: هدى عواض ظافر البكري | D8: 1090590280 | E8: سعودية | F8: 507557516 | G8: 3979@altanmiyah.edu.sa | H8: بكالوريوس | I8: تصوير تشكيلي و طباعة | J8: فنية | K8: ابتدائي | L8: 1 | M8: اسرية-بدنية
A9: 4 | B9: 186 | C9: عهود فالح بن فاتل الرويلي | D9: 1072851387 | E9: سعودية | F9: 555958725 | G9: o.alruwaili@altanmiyah.edu.sa | H9: بكالوريوس | I9: لغة انجليزية | J9: لغة انجليزية | K9: ابتدائي | L9: 0 | M9: بدنية
A10: 5 | B10: 258 | C10: نوف عائش بن شليويح الزلفي | D10: 1039555444 | E10: سعودية | F10: 535750688 | G10: N.ALZULFI@ALTanmiyah.edu.sa | H10: بكالوريوس | I10: رياضيات | J10: رياضيات | K10: ابتدائي | L10: 0 | M10: اسرية
A11: 6 | B11: 4613 | C11: أشواق خالد سحلي السلمي العنزي | D11: 1100642105 | E11: سعودية | F11: 564299881 | G11: 4613@altanmiyah.edu.sa | H11: بكالوريوس | I11: لغة عربية | J11: لغة عربية | K11: ابتدائي | L11: 1 | M11: اسلاميات
A12: 7 | B12: 4665 | C12: سارة منيف غزاي المخلفي | D12: 1109240026 | E12: سعودية | F12: 554020886 | G12: 4665@altanmiyah.edu.sa | H12: بكالوريوس | I12: دراسات اسلامية | J12: اسلاميات | K12: ابتدائي | L12: 1 | M12: اجتماعيات
A13: 8 | B13: 4839 | C13: نوضا سعيد سعود المطيري | D13: 1087563092 | E13: سعودية | F13: 504439030 | G13: 4839@altanmiyah.edu.sa | H13: بكالوريوس | I13: رياضيات | J13: رياضيات | K13: ابتدائي | L13: 1
A14: 9 | B14: 4073 | C14: نورا مجدي جلال محمود | D14: 3183302037 | E14: مصرية | F14: 96893292767 | G14: 4073@altanmiyah.edu.sa | H14: بكالوريوس | I14: لغة انجليزية | J14: لغة انجليزية | K14: ابتدائي | L14: 0
A15: 1 | B15: 4454 | C15: حنان خالد عبدالمحسن الغربي | D15: 1040870246 | E15: سعودية | F15: 533694533 | G15: 4454@altanmiyah.edu.sa | H15: بكالوريوس | I15: اجتماعيات | J15: اجتماعيات | K15: متوسط | L15: 1 | M15: تاريخ - بحث - مجال اختياري - اسرية
A16: 2 | B16: 777 | C16: حنان مطيران رجاء العنزي | D16: 1032078469 | E16: سعودية | F16: 501195488 | G16: 777@altanmiyah.edu.sa | H16: بكالوريوس | I16: لغة انجليزية | J16: لغة انجليزية | K16: متوسط | L16: 1 | M16: بدنية-رقمية
A17: 3 | B17: 3207 | C17: نهال سليمان محمد الشبرمي | D17: 1086472568 | E17: سعودية | F17: 500131813 | G17: 3207@altanmiyah.edu.sa | H17: بكالوريوس | I17: دراسات إسلامية | J17: اسلاميات | K17: متوسط | L17: 1 | M17: اجتماعيات - اسرية - ناقد - رقمية
A18: 4 | B18: 4838 | C18: الجوهرة رجاء جالي المخلفي | D18: 1090199421 | E18: سعودية | F18: 535311125 | G18: 4838@altanmiyah.edu.sa | H18: بكالوريوس | I18: لغة عربية | J18: لغة عربية | K18: متوسط | L18: 1 | M18: بدنية - رقمية
A19: 1 | B19: 191 | C19: سلطانه مدعث عوانان البقمي | D19: 1078713391 | E19: سعودية | F19: 551491226 | G19: S.Albaqmi@altanmiyah.edu.sa | H19: بكالوريوس | I19: رياضيات | J19: رياضيات | K19: ثانوي | L19: 0 | M19: بدنية
A20: 2 | B20: 4467 | C20: سلطانة فرحان عوض العصيمي العتيبي | D20: 1106877986 | E20: سعودية | F20: 538898978 | G20: 4467@altanmiyah.edu.sa | H20: بكالوريوس | I20: فيزياء | J20: فيزياء | K20: ثانوي | L20: 0 | M20: علوم
A21: 3 | B21: 175 | C21: نوف سليمان بن علي العتيبي | D21: 1046735476 | E21: سعودية | F21: 557553982 | G21: Nouf.alotaibi@altanmiyah.edu.sa | H21: بكالوريوس | I21: لغة عربية | J21: لغة عربية | K21: ثانوي | L21: 1 | M21: بدنية
A22: 4 | B22: 1768 | C22: هدى سعد نافع المطيري | D22: 1045321450 | E22: سعودية | F22: 563268883 | G22: h.almutairy@dab-schools.edu.sa | H22: بكالوريوس | I22: كيمياء | J22: كيمياء | K22: ثانوي | L22: 1 | M22: علوم
A23: 5 | C23: ديما
A24: 6 | B24: 3409 | C24: بدور نشاء دخيل الله البقمي | D24: 1085724225 | E24: سعودية | F24: 533260893 | G24: 3409@altanmiyah.edu.sa | H24: بكالوريوس | I24: رياضيات | J24: رياضيات | K24: ثانوي | L24: 0
A25: 7 | B25: 3213 | C25: ريم محمد بعيجان الحربي | D25: 1058962182 | E25: سعودية | F25: 508187827 | G25: 3213@altanmiyah.edu.sa | H25: بكالوريوس | I25: دراسات اسلامية | J25: اسلاميات | K25: ثانوي | L25: 1 | M25: ناقد - مجال اخياري
A26: 8 | B26: 3284 | C26: أمل سلمان عبيد العنزي | D26: 1067909166 | E26: سعودية | F26: 533350378 | G26: 3284@altanmiyah.edu.sa | H26: بكالوريوس | I26: ادب انجليزي | J26: لغة انجليزية | K26: ثانوي | L26: 0 | M26: بدنية
A27: 9 | B27: 4840 | C27: نوير عقيل محارب الشمري | D27: 1093886594 | E27: سعودية | F27: 556970857 | G27: 4840@altanmiyah.edu.sa | H27: بكالوريوس | I27: حاسب | J27: مهارات رقمية | K27: ثانوي | L27: 1
A28: 10 | B28: 3847 | C28: أماني فهمي جمال لاشين | D28: 2581547557 | E28: مصرية | F28: 548221528 | G28: 3847@altanmiyah.edu.sa | H28: بكالوريوس | I28: العلوم البيولوجية | J28: احياء | K28: ثانوي | L28: 0 | M28: علوم
G33: المرحلة | H33: عدد المعلمات | J33: الاجمالي | K33: الرخصة المهنية
H34: سعودي | I34: غير سعودي
G35: تمهيدي | H35: 2 | I35: 0 | J35: =SUM(H35:I35) -> 2 | K35: =SUM(L4:L5) -> 2
G36: ابتدائي بنات | H36: 8 | I36: 1 | J36: =SUM(H36:I36) -> 9 | K36: =SUM(L6:L14) -> 6
G37: متوسط بنات | H37: 4 | I37: 0 | J37: =SUM(H37:I37) -> 4 | K37: =SUM(L15:L18) -> 4
G38: ثانوي بنات | H38: 9 | I38: 1 | J38: =SUM(H38:I38) -> 10 | K38: =SUM(L19:L28) -> 4
G39: إجمالي المعلمات | H39: =SUM(H35:H38) -> 23 | I39: =SUM(I35:I38) -> 2 | J39: =SUM(J35:J38) -> 25 | K39: =SUM(K35:K38) -> 16

Sheet إدارة المجمع
B1: ادارة المجمع
B2: رقم وظيفي | C2: اسم الموظفة رباعي | D2: الوظيفة | E2: المرحلة | F2: رقم الهوية | G2: الجنسية | H2: رقم الجوال | I2: الإيميل | J2: المؤهل | K2: التخصص | L2: رخصة
B3: 4600 | C3: الجوهرة بنت سعود بن سعد البالود | D3: وكيل | E3: إدارة المجمع | G3: سعودية | I3: Aljoharah.albaloud@altanmiyah.edu.sa | J3: بكالوريوس | K3: تربية فنية
B4: 21 | C4: ياسر علواني حفني حسن | D4: سكرتير | E4: إدارة المجمع | F4: 2295980011 | G4: مصري | H4: 595617259 | I4: y.hassan@altanmiyah.edu.sa | J4: بكالوريوس | K4: رياضيات
B5: 185 | C5: أمينه صالح معيتق الحربي | D5: مشرف مقيم | E5: قسم البنات | G5: سعودية | I5: Amina.Alharbi@altanmiyah.edu.sa
B6: 114 | C6: محمد مصطفى سنهابي | D6: مشرف مقيم | E6: قسم البنين | F6: 2372202024 | G6: مصري | H6: 531504194 | I6: M.Sanhabi@altanmiyah.edu.sa | J6: بكالوريوس دار علوم | K6: لغة عربية

Sheet اداريين دار القلم
B1: اداريين قسم البنين
B2: إداريين المرحلة الابتدائية بنين
B3: رقم وظيفي | C3: اسم الموظفة رباعي | D3: الوظيفة | E3: المرحلة | F3: رقم الهوية | G3: الجنسية | H3: رقم الجوال | I3: الإيميل | J3: المؤهل | K3: التخصص | L3: الرخصة المهنية
B4: 24 | C4: عمرو عبدالتواب عطا | D4: وكيل | E4: الابتدائي | F4: 2312391994 | G4: مصري | H4: 541219474 | I4: 24@altanmiyah.edu.sa | J4: بكالوريوس | K4: رياضيات
B5: 80 | C5: الزين الشيخ الزين أبوجبل | D5: وكيل | E5: المتوسطة | F5: 2576598045 | G5: سوداني | H5: 535311347 | I5: 80@altanmiyah.edu.sa | J5: بكالوريوس | K5: لغة انجليزية
B6: 3503 | C6: محمد مدين عبدالصادق عبدالقادر | D6: رائد نشاط | E6: الابتدائي | G6: مصري | I6: 3503@altanmiyah.edu.sa | J6: بكالوريوس خدمة اجتماعية | K6: اجتماع
B8: إداريين المرحلة المتوسطة بنين
B9: رقم وظيفي | C9: اسم الموظفة رباعي | D9: الوظيفة | E9: المرحلة | F9: رقم الهوية | G9: الجنسية | H9: رقم الجوال | I9: الإيميل | J9: المؤهل | K9: التخصص | L9: الرخصة المهنية
B10: 93 | C10: قصي حسن حسن زقزاق | D10: وكيل | E10: الثانوية | F10: 2295725507 | G10: مصر | H10: 538774812 | I10: Q.Zaqzaq@altanmiyah.edu.sa | J10: بكالوريوس علوم | K10: علوم
B11: 4033 | C11: خالد سعود عجيز العتيبي | D11: موجه طلابي | E11: الثانوية | F11: 1107682567 | G11: سعودي | H11: 533977767 | I11: 4033@altanmiyah.edu.sa | J11: بكالوريوس | K11: علم نفس
B13: إداريين المرحلة الثانوية بنين
B14: رقم وظيفي | C14: اسم الموظفة رباعي | D14: الوظيفة | E14: المرحلة | F14: رقم الهوية | G14: الجنسية | H14: رقم الجوال | I14: الإيميل | J14: المؤهل | K14: التخصص | L14: الرخصة المهنية
B15: 165 | C15: محمد مفرح عبدالعالي العنزي | D15: مدير مرحلة | E15: الثانوية | F15: 1086111679 | G15: السعودية | H15: 545389278 | I15: M.Mufreh@altanmiyah.edu.sa | J15: بكالوريوس اجتماع | K15: علم نفس
B16: 89 | C16: مصطفى رجب جمعه العباسي | D16: وكيل | E16: الثانوية | F16: 2295984575 | G16: مصري | H16: 546786061 | I16: B.Deputy.Sec_Daq@Altanmiyah.edu.sa | J16: بكالوريوس تربية | K16: لغة انجليزية
B17: 2625 | C17: مشعل حمود الرمالي الشمري | D17: موجه طلابي | E17: الثانوية | F17: 1096150808 | G17: سعودي | H17: 555829588 | I17: Meshaal.Alshammari@altanmiyah.edu.sa | J17: ماجستير | K17: توجيه وإرشاد نفسي
B18: 155 | C18: احمد رفعت حامد السعدني | D18: رائد نشاط | E18: الثانوية | F18: 2396958551 | G18: مصري | H18: 582108151 | I18: A.Alsaadani@altanmiyah.edu.sa | J18: بكالوريوس التربية النوعية | K18: إعلام تربوي
B19: 65 | C19: عبد العزيز خالد عبد العزيز العتيق | D19: مساعد اداري | E19: الثانوية | F19: 1073686394 | G19: سعودي | H19: 545069043 | I19: A.Alateeq@altanmiyah.edu.sa | J19: بكالوريوس | K19: اصول دين
B20: 2529 | C20: سعود محمد فيحان المطيري | D20: رائد نشاط | E20: الثانوية | F20: 1081571646 | G20: السعودية | H20: 558158466 | I20: saud.almutairi@altanmiyah.edu.sa | J20: بكالوريوس رياضيات | K20: رياضيات
C24: الإداريين
C25: مرحلة | D25: سعودي | E25: غير سعودي | F25: المجموع | G25: الرخصة المهنية
C26: ابتدائي | D26: 0 | E26: 3 | F26: =SUM(D26:E26) -> 3 | G26: =L4+L5+L6+L7 -> 0
C27: متوسط | D27: 1 | E27: 1 | F27: =SUM(D27:E27) -> 2 | G27: =L10+L11+L12 -> 0
C28: ثانوي | D28: 4 | E28: 2 | F28: =SUM(D28:E28) -> 6 | G28: =L15+L16+L17+L18+L19+L20+L21 -> 0
C29: المجموع | D29: =SUM(D26:D28) -> 5 | E29: =SUM(E26:E28) -> 6 | F29: =SUM(F26:F28) -> 11 | G29: =SUM(G26:G28) -> 0

Sheet اداريات دار القلم
B1: ادارة المجمع
B2: إداريات رياض الأطفال
B3: م | C3: اسم الموظفة رباعي | D3: الوظيفة | E3: المرحلة | F3: رقم الهوية | G3: الجنسية | H3: رقم الجوال | I3: الإيميل | J3: المؤهل | K3: التخصص | L3: ملاحظات
B4: 0 | C4: 0 | D4: 0 | E4: 0 | F4: 0 | G4: 0 | H4: 0 | I4: 0 | J4: 0 | K4: 0 | L4: 0
B5: إداريات المرحلة الابتدائية بنات
B6: رقم وظيفي | C6: اسم الموظفة رباعي | D6: الوظيفة | E6: المرحلة | F6: رقم الهوية | G6: الجنسية | H6: رقم الجوال | I6: الإيميل | J6: المؤهل | K6: التخصص | L6: الرخصة المهنية
B7: 215 | C7: ريما فهد القحطاني | D7: وكيلة | E7: ابتدائي | G7: سعودية
B8: 2461 | C8: نوره منصور بن هجرس العتيبي | D8: موجهة طلابية | E8: ابتدائي | F8: 1094668694 | G8: سعودية | H8: 558535905 | I8: Noura.alotaibi@altanmiyah.edu.sa | J8: بكالوريوس | K8: خدمة اجتماعيه | L8: 0
B11: إداريات المرحلة المتوسطة بنات
B12: رقم وظيفي | C12: اسم الموظفة رباعي | D12: الوظيفة | E12: المرحلة | F12: رقم الهوية | G12: الجنسية | H12: رقم الجوال | I12: الإيميل | J12: المؤهل | K12: التخصص | L12: الرخصة المهنية
B13: 192 | C13: لطيفه سعد عبد الرحمن المسعر | D13: محضرة مختبر | E13: المتوسطة | F13: 1082129105 | G13: سعودية | H13: 539121234 | I13: l.almasaar@altanmiyah.edu.sa | J13: بكالوريوس | K13: كيمياء | L13: 0
B14: 1794 | C14: نورة عبد الرحمن صالح العيسى | D14: مساعد اداري | E14: المتوسطة | F14: 1062623994 | G14: سعودية | H14: 509330086 | I14: n.alaesa@dab-schools.edu.sa | J14: بكالوريوس | K14: مكتبات ومعلومات | L14: 1
B18: إداريات المرحلة الثانوية بنات
B19: رقم وظيفي | C19: اسم الموظفة رباعي | D19: الوظيفة | E19: المرحلة | F19: رقم الهوية | G19: الجنسية | H19: رقم الجوال | I19: الإيميل | J19: المؤهل | K19: التخصص | L19: الرخصة المهنية
B20: 208 | C20: حميده فلاح حميدي العنزي | D20: مديرة | E20: الثانوية | F20: 1000674232 | G20: سعودية | H20: 544613987 | I20: G.principal.Sec_Daq@altanmiyah.edu.sa | J20: بكالوريوس | K20: لغة عربية | L20: 1
B21: 177 | C21: ريم قاسم داخل البقمي | D21: وكيلة | E21: الثانوية | F21: 1096143985 | G21: سعودية | H21: 535310618 | I21: R.Albaqmi@altanmiyah.edu.sa | J21: بكالوريوس | K21: لغة عربية | L21: 1
B22: 183 | C22: خلود محمد حسن حدادي | D22: موجهه طلابية | E22: الثانوية | F22: 1065196212 | G22: سعودية | H22: 506056773 | I22: K.Haddadi@altanmiyah.edu.sa | J22: بكالوريوس | K22: علم اجتماع و الخدمة اجتماعية | L22: 0
B23: 281 | C23: نوره صالح محمد السجاء | D23: رائدة نشاط | E23: الثانوية | F23: 1088571292 | G23: سعودية | H23: 504436877 | I23: N.alsajaa@altanmiyah.edu.sa | J23: بكالوريوس | K23: ملابس ونسيج | L23: 1
C29: اداريات بنات كأفراد
C30: مرحلة | D30: سعودية | E30: غير سعودية | F30: المجموع | G30: الرخصة المهنية
C31: رياض اطفال | D31: 0 | E31: 0 | F31: =SUM(D31:E31) -> 0 | G31: =L4 -> 0
C32: ابتدائي | D32: 2 | E32: 0 | F32: =SUM(D32:E32) -> 2 | G32: =L7+L8+L9+L10 -> 0
C33: متوسط | D33: 2 | E33: 0 | F33: =SUM(D33:E33) -> 2 | G33: =L13+L14+L15+L16+L17 -> 1
C34: ثانوي | D34: 4 | E34: 0 | F34: =SUM(D34:E34) -> 4 | G34: =L20+L21+L22+L23+L24+L25+L26 -> 3
C35: المجموع | D35: =SUM(D31:D34) -> 8 | E35: =SUM(E31:E34) -> 0 | F35: =SUM(F31:F34) -> 8 | G35: =SUM(G31:G34) -> 4

Sheet شواغر دار القلم
A1: شواغر مجمع دار القلم
A2: قسم البنات | B2: التمهيدي | C2: عدد الفصول | D2: عدد الطلاب | E2: الشواغر | F2: ابتدائي بنات | G2: عدد الفصول | H2: عدد الطلاب | I2: الشواغر | J2: متوسط بنات | K2: عدد الفصول | L2: عدد الطلاب | M2: الشواغر | N2: ثانوي بنات | O2: عدد الفصول | P2: عدد الطلاب | Q2: الشواغر
B3: KG1 | C3: ='إحصاء الطلاب'!E3 -> 1 | D3: ='إحصاء الطلاب'!I3 -> 6 | E3: =(C3*25)-D3 -> 19 | F3: الصف الأول | G3: ='إحصاء الطلاب'!E7+'إحصاء الطلاب'!E8 -> 1 | H3: ='إحصاء الطلاب'!I7 -> 11 | I3: =(G3*25)-H3 -> 14 | J3: الصف الأول | K3: ='إحصاء الطلاب'!E29 -> 1 | L3: ='إحصاء الطلاب'!I29 -> 14 | M3: =(K3*25)-L3 -> 11 | N3: الصف الأول | O3: ='إحصاء الطلاب'!E44 -> 2 | P3: ='إحصاء الطلاب'!I44 -> 48 | Q3: =(O3*25)-P3 -> 2
B4: KG2 | C4: ='إحصاء الطلاب'!E4 -> 1 | D4: ='إحصاء الطلاب'!I4 -> 16 | E4: =(C4*25)-D4 -> 9 | F4: الصف الثاني | G4: ='إحصاء الطلاب'!E9+'إحصاء الطلاب'!E10 -> 1 | H4: ='إحصاء الطلاب'!I9 -> 17 | I4: =(G4*25)-H4 -> 8 | J4: الصف الثاني | K4: ='إحصاء الطلاب'!E30 -> 1 | L4: ='إحصاء الطلاب'!I30 -> 19 | M4: =(K4*25)-L4 -> 6 | N4: الصف الثاني | O4: ='إحصاء الطلاب'!E45 -> 3 | P4: ='إحصاء الطلاب'!I45 -> 72 | Q4: =(O4*25)-P4 -> 3
B5: KG3 | C5: ='إحصاء الطلاب'!E5 -> 1 | D5: ='إحصاء الطلاب'!I5 -> 21 | E5: =(C5*25)-D5 -> 4 | F5: الصف الثالث | G5: ='إحصاء الطلاب'!E11+'إحصاء الطلاب'!E12 -> 2 | H5: ='إحصاء الطلاب'!I11 -> 37 | I5: =(G5*25)-H5 -> 13 | J5: الصف الثالث | K5: ='إحصاء الطلاب'!E31 -> 1 | L5: ='إحصاء الطلاب'!I31 -> 15 | M5: =(K5*25)-L5 -> 10 | N5: الصف الثالث | O5: ='إحصاء الطلاب'!E49 -> 2 | P5: ='إحصاء الطلاب'!I49 -> 69 | Q5: =(O5*25)-P5 -> -19
B6: اجمالي الشواغر | C6: =E3+E4+E5 -> 32 | F6: الصف الرابع | G6: ='إحصاء الطلاب'!E13+'إحصاء الطلاب'!E14 -> 1 | H6: ='إحصاء الطلاب'!I13 -> 22 | I6: =(G6*25)-H6 -> 3 | J6: اجمالي الشواغر | K6: =M3+M4+M5 -> 27 | N6: اجمالي الشواغر | O6: =Q3+Q4+Q5 -> -14
F7: الصف الخامس | G7: ='إحصاء الطلاب'!E15 -> 1 | H7: ='إحصاء الطلاب'!I15 -> 14 | I7: =(G7*25)-H7 -> 11
F8: الصف السادس | G8: ='إحصاء الطلاب'!E16 -> 1 | H8: ='إحصاء الطلاب'!G16 -> 9 | I8: =(G8*25)-H8 -> 16
F9: اجمالي الشواغر | G9: =I3+I4+I5+I6+I7+I8 -> 65
A11: قسم البنين | B11: ابتدائي بنين | C11: عدد الفصول | D11: عدد الطلاب | E11: الشواغر | F11: متوسط بنين | G11: عدد الفصول | H11: عدد الطلاب | I11: الشواغر | J11: ثانوي بنين | K11: عدد الفصول | L11: عدد الطلاب | M11: الشواغر
B12: الصف الأول | C12: ='إحصاء الطلاب'!E18 -> 2 | D12: ='إحصاء الطلاب'!I18 -> 44 | E12: =(C12*25)-D12 -> 6 | F12: الصف الأول | G12: ='إحصاء الطلاب'!E25 -> 3 | H12: ='إحصاء الطلاب'!I25 -> 69 | I12: =(G12*25)-H12 -> 6 | J12: الصف الأول | K12: ='إحصاء الطلاب'!E33+'إحصاء الطلاب'!E34 -> 8 | L12: ='إحصاء الطلاب'!I33+'إحصاء الطلاب'!I34 -> 203 | M12: =(K12*25)-L12 -> -3
B13: الصف الثاني | C13: ='إحصاء الطلاب'!E19 -> 2 | D13: ='إحصاء الطلاب'!I19 -> 42 | E13: =(C13*25)-D13 -> 8 | F13: الصف الثاني | G13: ='إحصاء الطلاب'!E26 -> 3 | H13: ='إحصاء الطلاب'!I26 -> 67 | I13: =(G13*25)-H13 -> 8 | J13: الصف الثاني | K13: ='إحصاء الطلاب'!E35+'إحصاء الطلاب'!E36 -> 8 | L13: ='إحصاء الطلاب'!I35+'إحصاء الطلاب'!I36 -> 224 | M13: =(K13*25)-L13 -> -24
B14: الصف الثالث | C14: ='إحصاء الطلاب'!E20 -> 2 | D14: ='إحصاء الطلاب'!I20 -> 36 | E14: =(C14*25)-D14 -> 14 | F14: الصف الثالث | G14: ='إحصاء الطلاب'!E27 -> 3 | H14: ='إحصاء الطلاب'!I27 -> 68 | I14: =(G14*25)-H14 -> 7 | J14: الصف الثالث | K14: ='إحصاء الطلاب'!E39 -> 7 | L14: ='إحصاء الطلاب'!I39 -> 237 | M14: =(K14*25)-L14 -> -62
B15: الصف الرابع | C15: ='إحصاء الطلاب'!E21 -> 3 | D15: ='إحصاء الطلاب'!I21 -> 61 | E15: =(C15*25)-D15 -> 14 | F15: اجمالي الشواغر | G15: =I12+I13+I14 -> 21 | J15: اجمالي الشواغر | K15: =M12+M13+M14 -> -89
B16: الصف الخامس | C16: ='إحصاء الطلاب'!E22 -> 2 | D16: ='إحصاء الطلاب'!I22 -> 52 | E16: =(C16*25)-D16 -> -2
B17: الصف السادس | C17: ='إحصاء الطلاب'!E23 -> 2 | D17: ='إحصاء الطلاب'!I23 -> 38 | E17: =(C17*25)-D17 -> 12
B18: اجمالي الشواغر | C18: =E12+E13+E14+E15+E16+E17 -> 52

Sheet مقارنة النمو
A1: مقارنة النمو بين اغلاق عام ١٤٤٦ وبداية عام ١٤٤٧
A2: البيان | B2: تمهيدي | C2: ابتدائي بنات | D2: متوسط بنات | E2: ثانوي بنات | F2: ابتدائي بنين | G2: متوسط بنين | H2: ثانوي بنين | I2: مسار نون | J2: اجمالي المجمع
A3: اغلاق ١٤٤٦ | B3: 24 | C3: 115 | D3: 51 | E3: 201 | F3: 243 | G3: 163 | H3: 313 | I3: 0 | J3: =SUM(B3:I3) -> 1110
A4: بدء ١٤٤٧ | B4: 35 | C4: 98 | D4: 47 | E4: 171 | F4: 267 | G4: 173 | H4: 325 | I4: 52 | J4: =SUM(B4:I4) -> 1168
A5: حالة النمو بداية الفصل الأول | B5: =B4-B3 -> 11 | C5: =C4-C3 -> -17 | D5: =D4-D3 -> -4 | E5: =E4-E3 -> -30 | F5: =F4-F3 -> 24 | G5: =G4-G3 -> 10 | H5: =H4-H3 -> 12 | I5: =I4-I3 -> 52 | J5: =J4-J3 -> 58
A6: مقارنة النمو بين اغلاق الفصل الدراسي الأول ١٤٤٧ وبداية الفصل الدراسي الثاني ١٤٤٧
A7: اغلاق الفصل الدراسي الأول ١٤٤٧ | B7: 35 | C7: 98 | D7: 47 | E7: 171 | F7: 266 | G7: 207 | H7: 568 | I7: 52 | J7: =SUM(B7:I7) -> 1444
A8: المنسحبين بنهاية الفصل الدراسي الأول ١٤٤٧ | B8: 0 | C8: 2 | D8: 0 | E8: 3 | F8: 6 | G8: 3 | H8: 6 | I8: 1 | J8: =SUM(B8:I8) -> 21
A9: الطلاب المنقطعين وتم طي قيدهم | B9: 0 | C9: 0 | D9: 0 | E9: 0 | F9: 0 | G9: 3 | H9: 4 | I9: 0 | J9: =SUM(B9:I9) -> 7
A10: المسجلين الجدد بداية الفصل الدراسي الثاني ١٤٤٧ | B10: 4 | C10: 5 | D10: 1 | E10: 11 | F10: 4 | G10: 2 | H10: 21 | I10: 3 | J10: =SUM(B10:I10) -> 51
A11: حالة النمو بداية الفصل الثاني | B11: =B12-B7 -> 4 | C11: =C12-C7 -> 3 | D11: =D12-D7 -> 1 | E11: =E12-E7 -> 8 | F11: =F12-F7 -> -2 | G11: =G12-G7 -> -4 | H11: =H12-H7 -> 11 | I11: =I12-I7 -> 2 | J11: =J12-J7 -> 23
A12: اجمالي المجمع | B12: =(B7-(B8+B9)+B10) -> 39 | C12: =(C7-(C8+C9)+C10) -> 101 | D12: =(D7-(D8+D9)+D10) -> 48 | E12: =(E7-(E8+E9)+E10) -> 179 | F12: =(F7-(F8+F9)+F10) -> 264 | G12: =(G7-(G8+G9)+G10) -> 203 | H12: =(H7-(H8+H9)+H10) -> 579 | I12: =(I7-(I8+I9)+I10) -> 54 | J12: =(J7-(J8+J9)+J10) -> 1467
A13: العدد بالحلول | B13: 39 | C13: 107 | D13: 48 | E13: 180 | F13: 267 | G13: 202 | H13: 583 | I13: 54 | J13: =SUM(B13:I13) -> 1480

Sheet الإحصاء العام للمجمع
A1: احصاء العاملين بالمجمع
A2: المرحلة | B2: الجنس | D2: معلمين - معلمات | F2: اداريين - اداريات | H2: عامل - عاملة | I2: سائق | J2: حارس | K2: إجمالي الطواقم
D4: سعودي | E4: غير سعودي | F4: سعودي | G4: غير سعودي
A5: ادارة المجمع | D5: 0 | E5: 0 | F5: 2 | G5: 2 | H5: 1 | I5: 0 | J5: 0 | K5: =SUM(D5:J5) -> 5
A6: تربية خاصة | B6: بنات | D6: 0 | E6: 0 | F6: 0 | G6: 0 | H6: 0 | I6: 0 | J6: 0 | K6: 0
B7: بنين | D7: 0 | E7: 0 | F7: 0 | G7: 0 | H7: 0 | I7: 0 | J7: 0 | K7: 0
A8: تمهيدي | B8: بنات | D8: 2 | E8: 0 | F8: 1 | G8: 0 | H8: 1 | I8: 0 | J8: 0 | K8: =SUM(D8:J8) -> 4
A9: ابتدائي | B9: بنين | D9: 1 | E9: 17 | F9: 0 | G9: 3 | H9: 2 | I9: 0 | J9: 1 | K9: =SUM(D9:J9) -> 24
B10: بنات | D10: 8 | E10: 1 | F10: 1 | G10: 0 | H10: 1 | I10: 0 | J10: 1 | K10: =SUM(D10:J10) -> 12
A11: متوسط | B11: بنين | D11: 3 | E11: 10 | F11: 1 | G11: 1 | H11: 0 | I11: 0 | J11: 0 | K11: =SUM(D11:J11) -> 15
B12: بنات | D12: 4 | E12: 0 | F12: 1 | G12: 0 | H12: 0 | I12: 0 | J12: 0 | K12: =SUM(D12:J12) -> 5
A13: ثانوي | B13: بنين | D13: 4 | E13: 23 | F13: 4 | G13: 2 | H13: 2 | I13: 0 | J13: 1 | K13: =SUM(D13:J13) -> 36
B14: بنات | D14: 9 | E14: 1 | F14: 5 | G14: 0 | H14: 0 | I14: 0 | J14: 0 | K14: =SUM(D14:J14) -> 15
A15: اجماليات المجمع | B15: الفئة | D15: اجماليات
B16: معلمين | D16: =D9+D11+D13 -> 8 | E16: =E9+E11+E13 -> 50 | I16: اجمالي معلمين | K16: =SUM(D16:E16) -> 58
B17: معلمات | D17: =D8+D10+D12+D14 -> 23 | E17: =E8+E10+E12+E14 -> 2 | I17: اجمالي معلمات | K17: =SUM(D17:E17) -> 25
B18: اداريين | D18: =F9+F11+F13 -> 5 | E18: =G9+G11+G13 -> 6 | I18: اجمالي اداريين | K18: =SUM(D18:E18) -> 11
B19: اداريات | D19: =F8+F10+F12+F14 -> 8 | E19: =G8+G10+G12+G14 -> 0 | I19: اجمالي اداريات | K19: =SUM(D19:E19) -> 8
B20: خدمات مساندة | D20: عمال | E20: =SUM(H5:H14) -> 7
D21: سائقين | E21: 0
D22: حارس | E22: =SUM(J5:J14) -> 3
B23: الطواقم | D23: طاقم تعليمي | E23: طاقم اداري | F23: خدمات مساندة | H23: إدارة تشغيلية عامة | I23: إدارة المجمع | K23: اجمالي المجمع
F24: داخلي | G24: خارجي
B25: الإجمالي | D25: =K16+K17 -> 83 | E25: =K18+K19 -> 19 | F25: =E20+E22 -> 10 | G25: 3 | H25: 2 | I25: =F5+G5 -> 4 | K25: =SUM(D25:I25) -> 121

Sheet بيانات رواتب دار القلم
A1: ر.الموظف | B1: القسم | C1: اسم الموظف | D1: ملاحظات | E1: المدير المباشر | F1: تاريخ الميلاد | G1: ر.الهويه | H1: تاريخ المباشرة | I1: تاريخ التعيين | J1: الفئة الوظيفية | K1: علي رأس العمل | L1: الجنسيـــــــة | M1: الديانة | N1: الحالة الاجتماعية | O1: مكان الميلاد | P1: مسؤول موارد بشرية | Q1: الوظيفة الحالية | R1: مده الخبره فى الخارج | S1: مده الخبره فى الداخل | T1: اجمالي الخبرة | U1: رقم الجوال | V1: رقم الجوال 2 | W1: رقم الهاتف | X1: البريد الالكتروني | Y1: شركة التأمين | Z1: اسم الفئة التأمينية | AA1: تاريخ بداية التأمين | AB1: تاريخ نهاية وثيقة التأمين | AC1: طريقة الدفع | AD1: IBAN | AE1: ر.البصمه | AF1: موقوف | AG1: المنطقة | AH1: الفرع
A2: 24 | B2: ابتدائي | C2: عمرو عبد التواب عطا عطية | E2: نورة محمد عاتق العتيبي | F2: 31370 | G2: 2312391994 | H2: 40974 | I2: 40974 | J2: مقيم تأمينات | K2: نعم | L2: مصر | M2: مسلم | N2: متزوج | O2: مصر | P2: لا | Q2: معلم | S2: 12 سنه 5 شهر 30 يوم | T2: 12 | U2: 540219538 | X2: 2312391994@al-tanmiah.com | AC2: بنك | AD2: SA0705000068203544457000 | AE2: 24 | AF2: لا | AG2: الرياض | AH2: مدارس دار القلم
A3: 25 | B3: إدارة المجمع | C3: محمود ابو الغيط عبد العاطى عبد الجليل | E3: معن هاني بن محمد البشر | F3: 32242 | G3: 2312390889 | H3: 40813 | I3: 40813 | J3: مقيم تأمينات | K3: نعم | L3: مصر | M3: مسلم | N3: متزوج | O3: مصر | P3: لا | Q3: منسق | S3: 12 سنه 11 شهر 9 يوم | T3: 13 | U3: 540357053 | X3: 2312390889@al-tanmiah.com | AC3: بنك | AD3: SA2405000068201813540000 | AE3: 25 | AF3: لا | AG3: الرياض | AH3: مدارس دار القلم
A4: 26 | B4: ابتدائي | C4: طارق عبد الظاهر بيومي سيد أحمد | E4: نورة محمد عاتق العتيبي | F4: 23449 | G4: 2422170593 | H4: 42631 | I4: 42631 | J4: مقيم تأمينات | K4: نعم | L4: مصر | M4: مسلم | N4: متزوج | O4: مصر | P4: لا | Q4: معلم | S4: 7 سنه 11 شهر 18 يوم | T4: 8 | U4: 562987348 | X4: 2422170593@al-tanmiah.com | AC4: بنك | AD4: SA4805000068204540118000 | AE4: 26 | AF4: لا | AG4: الرياض | AH4: مدارس دار القلم
A5: 27 | B5: ابتدائي | C5: رامي محمد يسن معروف | E5: نورة محمد عاتق العتيبي | F5: 32599 | G5: 2422462180 | H5: 42634 | I5: 42634 | J5: مقيم تأمينات | K5: نعم | L5: مصر | M5: مسلم | N5: أعزب | O5: مصر | P5: لا | Q5: معلم | S5: 7 سنه 11 شهر 15 يوم | T5: 8 | U5: 580934865 | X5: 2422462180@al-tanmiah.com | AC5: بنك | AD5: SA0505000068204540105000 | AE5: 27 | AF5: لا | AG5: الرياض | AH5: مدارس دار القلم
A6: 28 | B6: ابتدائي | C6: محمد السيد كامل الغباشي | E6: نورة محمد عاتق العتيبي | F6: 30478 | G6: 2422497111 | H6: 42647 | I6: 42647 | J6: مقيم تأمينات | K6: نعم | L6: مصر | M6: مسلم | N6: متزوج | O6: مصر | P6: لا | Q6: معلم | S6: 7 سنه 11 شهر 1 يوم | T6: 8 | U6: 569424470 | X6: 2422497111@al-tanmiah.com | AC6: بنك | AD6: SA0705000068202521592000 | AE6: 28 | AF6: لا | AG6: الرياض | AH6: مدارس دار القلم
A7: 29 | B7: ابتدائي | C7: حسن علي ذياب الخطيب | E7: نورة محمد عاتق العتيبي | F7: 25231 | G7: 2295913624 | H7: 44430 | I7: 44430 | J7: مقيم تأمينات | K7: نعم | L7: الأردن | M7: مسلم | N7: متزوج | O7: الأردن | P7: لا | Q7: معلم | S7: 3 سنه 0 شهر 14 يوم | T7: 3 | U7: 568795892 | X7: 2295913624@al-tanmiah.com | AC7: بنك | AD7: SA5705000068201899501000 | AE7: 29 | AF7: لا | AG7: الرياض | AH7: مدارس دار القلم
A8: 30 | B8: متوسط | C8: ابو السعود معاويه ابو السعود محمد | E8: معن هاني بن محمد البشر | F8: 35797 | G8: 2474277379 | H8: 44452 | I8: 44452 | J8: مقيم تأمينات | K8: نعم | L8: السودان | M8: مسلم | N8: أعزب | O8: السودان | P8: لا | Q8: منقذ سباحة | S8: 2 سنه 11 شهر 23 يوم | T8: 3 | U8: 560508651 | X8: 2474277379@al-tanmiah.com | AC8: بنك | AD8: SA8305000068204505274000 | AE8: 30 | AF8: لا | AG8: الرياض | AH8: مدارس دار القلم
A9: 33 | B9: متوسط | C9: محمود صابر محمود سعيد | E9: نورة محمد عاتق العتيبي | F9: 31004 | G9: 2265322129 | H9: 39732 | I9: 39732 | J9: مقيم تأمينات | K9: نعم | L9: مصر | M9: مسلم | N9: متزوج | O9: مصر | P9: لا | Q9: معلم | S9: 15 سنه 10 شهر 25 يوم | T9: 16 | U9: 559462197 | X9: 2265322129@al-tanmiah.com | AC9: بنك | AD9: SA3005000068204495179000 | AE9: 33 | AF9: لا | AG9: الرياض | AH9: مدارس دار القلم
A10: 44 | B10: ثانوي | C10: امير ابراهيم جلال عبدالله | E10: نورة محمد عاتق العتيبي | F10: 30205 | G10: 2320558105 | H10: 40987 | I10: 40987 | J10: مقيم تأمينات | K10: نعم | L10: مصر | M10: مسلم | N10: متزوج | O10: مصر | P10: لا | Q10: معلم | S10: 12 سنه 5 شهر 17 يوم | T10: 12 | U10: 561584133 | X10: 2320558105@al-tanmiah.com | AC10: بنك | AD10: SA2105000068201450238000 | AE10: 44 | AF10: لا | AG10: الرياض | AH10: مدارس دار القلم
A11: 47 | B11: ثانوي | C11: أحمد محمد توفيق سالم | E11: نورة محمد عاتق العتيبي | F11: 31053 | G11: 2405280336 | H11: 42386 | I11: 42386 | J11: مقيم تأمينات | K11: نعم | L11: مصر | M11: مسلم | N11: أعزب | O11: مصر | P11: لا | Q11: معلم | S11: 8 سنه 7 شهر 19 يوم | T11: 8 | U11: 598871224 | X11: 2405280336@al-tanmiah.com | AC11: بنك | AD11: SA7305000068204496259000 | AE11: 47 | AF11: لا | AG11: الرياض | AH11: مدارس دار القلم
A12: 62 | B12: ثانوي | C12: عبدالملك عبدالكريم محمد اللاحم | E12: نورة محمد عاتق العتيبي | F12: 35642 | G12: 1098772732 | H12: 44445 | I12: 44445 | J12: سعودي تأمينات | K12: نعم | L12: السعودية | M12: مسلم | N12: أعزب | O12: السعودية | P12: لا | Q12: معلم | S12: 2 سنه 11 شهر 30 يوم | T12: 3 | U12: 552604731 | X12: 1098772732@al-tanmiah.com | AC12: بنك | AD12: SA4080000101608016319848 | AE12: 62 | AF12: لا | AG12: الرياض | AH12: مدارس دار القلم
A13: 65 | B13: متوسط | C13: عبدالعزيز خالد عبدالعزيز العتيق | E13: نورة محمد عاتق العتيبي | F13: 33103 | G13: 1073686394 | H13: 44593 | I13: 44593 | J13: سعودي تأمينات | K13: نعم | L13: السعودية | M13: مسلم | N13: أعزب | O13: السعودية | P13: لا | Q13: معلم | S13: 2 سنه 7 شهر 4 يوم | T13: 2 | U13: 545069043 | X13: 1073686394@al-tanmiah.com | AC13: بنك | AD13: SA8105000068204541398000 | AE13: 65 | AF13: لا | AG13: الرياض | AH13: مدارس دار القلم
... A19: 78 | B19: ابتدائي | C19: فواز عبدالله إسماعيل المطيري | E19: نورة محمد عاتق العتيبي | F19: 35369 | G19: 1095982995 | H19: 44593 | I19: 44593 | J19: سعودي تأمينات | K19: نعم | L19: السعودية | M19: مسلم | N19: أعزب | O19: السعودية | P19: لا | Q19: معلم | S19: 2 سنه 7 شهر 4 يوم | T19: 2 | U19: 501772544 | X19: 1095982995@al-tanmiah.com | AC19: بنك | AD19: SA3880000632608016034247 | AE19: 78 | AF19: لا | AG19: الرياض | AH19: مدارس دار القلم
A20: 80 | B20: متوسط | C20: الزين الشيخ الزين أبو جبل | F20: 25020 | G20: 2165144052 | H20: 45517 | I20: 43702 | J20: مقيم بدون تأمينات | K20: نعم | L20: السودان | M20: مسلم | N20: متزوج | O20: السودان | P20: لا | Q20: وكيل | S20: 5 سنه 0 شهر 11 يوم | T20: 5 | U20: 507237675 | X20: 2165144052@al-tanmiah.com | AC20: بنك | AD20: SA4080000539608019290980 | AE20: 80 | AF20: لا | AG20: الرياض | AH20: مدارس دار القلم
A21: 89 | B21: ثانوي | C21: مصطفى رجب جمعه العباسى | E21: نورة محمد عاتق العتيبي | F21: 29166 | G21: 2295984575 | H21: 40467 | I21: 40467 | J21: مقيم تأمينات | K21: نعم | L21: مصر | M21: مسلم | N21: متزوج | O21: مصر | P21: لا | Q21: معلم | S21: 13 سنه 10 شهر 20 يوم | T21: 14 | U21: 546786061 | X21: 2295984575@al-tanmiah.com | AC21: بنك | AD21: SA4105000068204496220000 | AE21: 89 | AF21: لا | AG21: الرياض | AH21: مدارس دار القلم
A22: 95 | B22: ثانوي | C22: احمد محمد مصباح عبعوب | E22: نورة محمد عاتق العتيبي | F22: 31357 | G22: 2350964611 | H22: 41512 | I22: 41512 | J22: مقيم تأمينات | K22: نعم | L22: مصر | M22: مسلم | N22: متزوج | O22: مصر | P22: لا | Q22: معلم | S22: 11 سنه 0 شهر 10 يوم | T22: 11 | U22: 552005145 | X22: 2350964611@al-tanmiah.com | AC22: بنك | AD22: SA9105000068204495802000 | AE22: 95 | AF22: لا | AG22: الرياض | AH22: مدارس دار القلم
A23: 96 | B23: ثانوي | C23: مصطفى ابراهيم عبدالتواب عبد المولي | E23: نورة محمد عاتق العتيبي | F23: 32888 | G23: 2382247068 | H23: 42057 | I23: 42057 | J23: مقيم تأمينات | K23: نعم | L23: مصر | M23: مسلم | N23: أعزب | O23: مصر | P23: لا | Q23: معلم | S23: 9 سنه 6 شهر 14 يوم | T23: 9 | U23: 552420543 | X23: 2382247068@al-tanmiah.com | AC23: بنك | AD23: SA8605000068204495999000 | AE23: 96 | AF23: لا | AG23: الرياض | AH23: مدارس دار القلم
A24: 98 | B24: ابتدائي | C24: محمود رضا ابوالمكارم وحش | E24: نورة محمد عاتق العتيبي | F24: 33512 | G24: 2396261717 | H24: 42235 | I24: 42235 | J24: مقيم تأمينات | K24: نعم | L24: مصر | M24: مسلم | N24: متزوج | O24: مصر | P24: لا | Q24: معلم | S24: 9 سنه 0 شهر 17 يوم | T24: 9 | U24: 599536762 | X24: 2396261717@al-tanmiah.com | AC24: بنك | AD24: SA1505000068204494315000 | AE24: 98 | AF24: لا | AG24: الرياض | AH24: مدارس دار القلم
A25: 111 | B25: ابتدائي | C25: عبد العزيز محمود بيومي يونس | E25: نورة محمد عاتق العتيبي | F25: 29967 | G25: 2314377397 | H25: 40847 | I25: 40847 | J25: مقيم تأمينات | K25: نعم | L25: مصر | M25: مسلم | N25: متزوج | O25: مصر | P25: لا | Q25: معلم | S25: 12 سنه 10 شهر 5 يوم | T25: 13 | U25: 598811372 | X25: 2314377397@al-tanmiah.com | AC25: بنك | AD25: SA3805000068202076809000 | AE25: 111 | AF25: لا | AG25: الرياض | AH25: مدارس دار القلم
A26: 122 | B26: ابتدائي | C26: محمود محمد محمود عبد الحسيب | E26: نورة محمد عاتق العتيبي | F26: 31643 | G26: 2422265567 | H26: 42638 | I26: 42638 | J26: مقيم تأمينات | K26: نعم | L26: مصر | M26: مسلم | N26: أعزب | O26: مصر | P26: لا | Q26: معلم | S26: 7 سنه 11 شهر 11 يوم | T26: 8 | U26: 560294799 | X26: 2422265567@al-tanmiah.com | AC26: بنك | AD26: SA2705000068204377675000 | AE26: 122 | AF26: لا | AG26: الرياض | AH26: مدارس دار القلم
A27: 137 | B27: ثانوي | C27: محمد صلاح أحمد نصر | E27: نورة محمد عاتق العتيبي | F27: 30514 | G27: 2422261525 | H27: 42637 | I27: 42637 | J27: مقيم تأمينات | K27: نعم | L27: مصر | M27: مسلم | N27: متزوج | O27: مصر | P27: لا | Q27: معلم | S27: 7 سنه 11 شهر 12 يوم | T27: 8 | U27: 548480212 | X27: 2422261525@al-tanmiah.com | AC27: بنك | AD27: SA5805000068204497335000 | AE27: 137 | AF27: لا | AG27: الرياض | AH27: مدارس دار القلم
A28: 155 | B28: إدارة المجمع | C28: احمد رفعت حامد السعدنى | E28: نورة محمد عاتق العتيبي | F28: 28917 | G28: 2396958551 | H28: 42988 | I28: 42988 | J28: مقيم تأمينات | K28: نعم | L28: مصر | M28: مسلم | N28: متزوج | O28: مصر | P28: لا | Q28: سكرتير مدير المجمع | S28: 6 سنه 11 شهر 26 يوم | T28: 7 | U28: 541397016 | X28: 2396958551@al-tanmiah.com | AC28: بنك | AD28: SA5205000068202989299000 | AE28: 155 | AF28: لا | AG28: الرياض | AH28: مدارس دار القلم
A29: 158 | B29: ثانوي | C29: أحمد طاهر عبد المعطي بهيدي | E29: نورة محمد عاتق العتيبي | F29: 33023 | G29: 2422266318 | H29: 42634 | I29: 42634 | J29: مقيم تأمينات | K29: نعم | L29: مصر | M29: مسلم | N29: أعزب | O29: مصر | P29: لا | Q29: معلم | S29: 7 سنه 11 شهر 15 يوم | T29: 8 | U29: 560000000 | X29: 2422266318@al-tanmiah.com | AC29: بنك | AD29: SA3205000068204375926000 | AE29: 158 | AF29: لا | AG29: الرياض | AH29: مدارس دار القلم
A30: 160 | B30: ثانوي | C30: سلمان محمد عبد الرحمن سالمان | E30: نورة محمد عاتق العتيبي | F30: 33454 | G30: 2442472367 | H30: 42988 | I30: 42988 | J30: مقيم تأمينات | K30: نعم | L30: مصر | M30: مسلم | N30: متزوج | O30: مصر | P30: لا | Q30: معلم | S30: 6 سنه 11 شهر 26 يوم | T30: 7 | U30: 545793386 | X30: 2442472367@al-tanmiah.com | AC30: بنك | AD30: SA3105000068203090211000 | AE30: 160 | AF30: لا | AG30: الرياض | AH30: مدارس دار القلم
A31: 164 | B31: ثانوي | C31: حسن أحمد ابو غنيمة أحمد | E31: نورة محمد عاتق العتيبي | F31: 33928 | G31: 2442117442 | H31: 42995 | I31: 42995 | J31: مقيم تأمينات | K31: نعم | L31: مصر | M31: مسلم | N31: متزوج | O31: مصر | P31: لا | Q31: معلم | S31: 6 سنه 11 شهر 19 يوم | T31: 7 | U31: 569484890 | X31: 2442117442@al-tanmiah.com | AC31: بنك | AD31: SA2105000068203617800000 | AE31: 164 | AF31: لا | AG31: الرياض | AH31: مدارس دار القلم
A32: 168 | B32: ثانوي | C32: حسام السيد محمد علي | E32: نورة محمد عاتق العتيبي | F32: 34869 | G32: 2479842896 | H32: 43788 | I32: 43788 | J32: مقيم تأمينات | K32: نعم | L32: مصر | M32: مسلم | N32: أعزب | O32: مصر | P32: لا | Q32: معلم | S32: 4 سنه 9 شهر 17 يوم | T32: 5 | U32: 542386188 | X32: 2479842896@al-tanmiah.com | AC32: بنك | AD32: SA7505000068203078661000 | AE32: 168 | AF32: لا | AG32: الرياض | AH32: مدارس دار القلم
... A43: 201 | B43: رياض أطفال | C43: ساره فهد عبدالله العجمي | E43: نورة محمد عاتق العتيبي | F43: 31650 | G43: 1070000169 | H43: 44640 | I43: 44640 | J43: سعودي تأمينات | K43: نعم | L43: السعودية | M43: مسلم | N43: متزوج | O43: السعودية | P43: لا | Q43: معلم | S43: 2 سنه 5 شهر 16 يوم | T43: 2 | U43: 551391313 | X43: 1070000169@al-tanmiah.com | AC43: بنك | AD43: SA8705000068204380937000 | AE43: 201 | AF43: لا | AG43: الرياض | AH43: مدارس دار القلم
A44: 208 | B44: إدارة المجمع | C44: حميده فلاح حميدي العنزي | F44: 27230 | G44: 1000674232 | H44: 43814 | I44: 43814 | J44: سعودي تأمينات | K44: نعم | L44: السعودية | M44: مسلم | N44: متزوج | O44: السعودية | P44: لا | Q44: مدير مجمع | S44: 4 سنه 8 شهر 21 يوم | T44: 5 | U44: 544613987 | X44: 1000674232@al-tanmiah.com | AC44: بنك | AD44: SA2205000068204495242000 | AE44: 208 | AF44: لا | AG44: الرياض | AH44: مدارس دار القلم
A45: 215 | B45: ابتدائي | C45: نورة مدعث عونان البقمي | E45: نورة محمد عاتق العتيبي | F45: 31071 | G45: 1078713367 | H45: 43009 | I45: 43009 | J45: سعودي تأمينات | K45: نعم | L45: السعودية | M45: مسلم | N45: متزوج | O45: السعودية | P45: لا | Q45: مدير مرحلة | S45: 6 سنه 11 شهر 4 يوم | T45: 7 | U45: 501949580 | X45: 1078713367@al-tanmiah.com | AC45: بنك | AD45: SA2605000068204080390000 | AE45: 215 | AF45: لا | AG45: الرياض | AH45: مدارس دار القلم
A46: 219 | B46: ابتدائي | C46: العنود عبد الله سفر الشيباني | E46: نورة محمد عاتق العتيبي | F46: 31800 | G46: 1067208841 | H46: 43009 | I46: 43009 | J46: سعودي تأمينات | K46: نعم | L46: السعودية | M46: مسلم | N46: متزوج | O46: السعودية | P46: لا | Q46: معلم | S46: 6 سنه 11 شهر 4 يوم | T46: 7 | U46: 559373729 | X46: 1067208841@al-tanmiah.com | AC46: بنك | AD46: SA2805000068204496480000 | AE46: 219 | AF46: لا | AG46: الرياض | AH46: مدارس دار القلم
A47: 258 | B47: ابتدائي | C47: نوف عائش شليويح الزلفي | E47: نورة محمد عاتق العتيبي | F47: 29812 | G47: 1039555444 | H47: 44472 | I47: 44472 | J47: سعودي تأمينات | K47: نعم | L47: السعودية | M47: مسلم | N47: متزوج | O47: السعودية | P47: لا | Q47: معلم | S47: 2 سنه 11 شهر 2 يوم | T47: 3 | U47: 535750688 | X47: 1039555444@al-tanmiah.com | AC47: بنك | AD47: SA6405000068204497797000 | AE47: 258 | AF47: لا | AG47: الرياض | AH47: مدارس دار القلم
A48: 277 | B48: ابتدائي | C48: منى مقبل عبد العزيز الخلف | E48: نورة محمد عاتق العتيبي | F48: 28647 | G48: 1030800088 | H48: 43009 | I48: 43009 | J48: سعودي تأمينات | K48: نعم | L48: السعودية | M48: مسلم | N48: متزوج | O48: السعودية | P48: لا | Q48: معلم | S48: 6 سنه 11 شهر 4 يوم | T48: 7 | U48: 555994993 | X48: 1030800088@al-tanmiah.com | AC48: بنك | AD48: SA5905000068204497800000 | AE48: 277 | AF48: لا | AG48: الرياض | AH48: مدارس دار القلم
A49: 281 | B49: متوسط | C49: نورة صالح محمد عبد الله السجاء | E49: نورة محمد عاتق العتيبي | F49: 31315 | G49: 1088571292 | H49: 43009 | I49: 43009 | J49: سعودي تأمينات | K49: نعم | L49: السعودية | M49: مسلم | N49: متزوج | O49: السعودية | P49: لا | Q49: معلم | S49: 6 سنه 11 شهر 4 يوم | T49: 7 | U49: 504436877 | X49: 1088571292@al-tanmiah.com | AC49: بنك | AD49: SA4305000068204497829000 | AE49: 281 | AF49: لا | AG49: الرياض | AH49: مدارس دار القلم
A50: 285 | B50: ابتدائي | C50: نوره عبد الله محماس المطيري | E50: نورة محمد عاتق العتيبي | F50: 32291 | G50: 1072522269 | H50: 44157 | I50: 44157 | J50: سعودي تأمينات | K50: نعم | L50: السعودية | M50: مسلم | N50: متزوج | O50: السعودية | P50: لا | Q50: معلم | S50: 3 سنه 9 شهر 14 يوم | T50: 4 | U50: 533216504 | X50: 1072522269@al-tanmiah.com | AC50: بنك | AD50: SA7105000068204495135000 | AE50: 285 | AF50: لا | AG50: الرياض | AH50: مدارس دار القلم
A51: 292 | B51: ثانوي | C51: بابكر محمد احمد الصديق | E51: معن هاني بن محمد البشر | F51: 21551 | G51: 2115422657 | H51: 42583 | I51: 42583 | J51: مقيم تأمينات | K51: نعم | L51: السودان | M51: مسلم | N51: متزوج | O51: السودان | P51: لا | Q51: حارس | S51: 8 سنه 1 شهر 4 يوم | T51: 8 | U51: 558281652 | X51: 2115422657@al-tanmiah.com | AC51: بنك | AD51: SA1505000068201296073001 | AE51: 292 | AF51: لا | AG51: الرياض | AH51: مدارس دار القلم
A52: 293 | B52: ابتدائي | C52: عاطف محمد ادريس محمد | E52: معن هاني بن محمد البشر | F52: 31413 | G52: 2276755655 | H52: 42583 | I52: 42583 | J52: مقيم تأمينات | K52: نعم | L52: السودان | M52: مسلم | N52: متزوج | O52: السودان | P52: لا | Q52: حارس | S52: 8 سنه 1 شهر 4 يوم | T52: 8 | U52: 552178464 | X52: 2276755655@al-tanmiah.com | AC52: بنك | AD52: SA1205000068202749733000 | AE52: 293 | AF52: لا | AG52: الرياض | AH52: مدارس دار القلم
A53: 297 | B53: ثانوي | C53: محمود حسين محمود فراج | E53: معن هاني بن محمد البشر | F53: 29587 | G53: 2210353526 | H53: 42583 | I53: 42583 | J53: مقيم تأمينات | K53: نعم | L53: مصر | M53: مسلم | N53: متزوج | O53: مصر | P53: لا | Q53: حارس | S53: 8 سنه 1 شهر 4 يوم | T53: 8 | U53: 57803303 | X53: 2210353526@al-tanmiah.com | AC53: بنك | AD53: SA9105000068204510352000 | AE53: 297 | AF53: لا | AG53: الرياض | AH53: مدارس دار القلم
A54: 315 | B54: ابتدائي | C54: شهيد الإسلام أنو مياه | E54: معن هاني بن محمد البشر | F54: 30746 | G54: 2268093669 | H54: 42590 | I54: 42590 | J54: مقيم تأمينات | K54: نعم | L54: بنجلاديش | M54: مسلم | N54: أعزب | O54: بنجلاديش | P54: لا | Q54: عامل | S54: 8 سنه 0 شهر 28 يوم | T54: 8 | U54: 530195994 | X54: 2268093669@al-tanmiah.com | AC54: بنك | AD54: SA9280000343608016061984 | AE54: 315 | AF54: لا | AG54: الرياض | AH54: مدارس دار القلم
A55: 320 | B55: ثانوي | C55: ناجندرا ساهـ | E55: معن هاني بن محمد البشر | F55: 28388 | G55: 2428893388 | H55: 42743 | I55: 42743 | J55: مقيم تأمينات | K55: نعم | L55: نيبالي | M55: مسلم | N55: أعزب | O55: نيبال | P55: لا | Q55: عامل | S55: 7 سنه 7 شهر 28 يوم | T55: 7 | U55: 500798586 | X55: 2428893388@al-tanmiah.com | AC55: بنك | AD55: SA5005000068204509329000 | AE55: 320 | AF55: لا | AG55: الرياض | AH55: مدارس دار القلم
...

Sheet اسناد بنين ف١
B2: اسنادات ابتدائي
A4: المعلم | B4: المادة | C4: عدد حصص المعلم بالمدرسة | D4: الإسناد | E4: إجمالي نصاب المعلم
A5: العفيفي عبد الجواد | B5: معلم صف أول | C5: 24 | D5: (٨) لغتي ص١+ (٤) اسلاميات ص١+ (٥) رياضيات ص١+ (٢) بدنية ص١+ (١) مهارات حياتية ص١ + (1) فنية ص١ + (3) علوم ص1 | E5: 24
A6: محمود عبدالحسيب | B6: معلم صف أول | C6: 24 | D6: (٨) لغتي ص١+ (٤) اسلاميات ص١+ (٥) رياضيات ص١+ (٢) بدنية ص١+ (١) مهارات حياتية ص١ + (1) فنية ص١ + (3) علوم ص1 | E6: 24
A7: عبد العزيز يونس | B7: معلم صف ثاني | C7: 24 | D7: (١٤) لغتي ص٢ فصلين + (١٠) اسلاميات ص٢ فصلين | E7: 24
A8: حسن عزالدين مبروك | B8: معلم صف ثالث | C8: 24 | D8: (١٤) لغتي ص٣ فصلين(2/4 ، 3/4) + (١٠) اسلاميات ص٣ فصلين +(٢) مهارات حياتية ص٣ فصلين | E8: 24
A9: سلمان حمد الفراج | B9: اسلاميات | C9: 24 | D9: (١٢) اسلاميات ص٤ فصلين (2/4 ،3/4)+ (٨) اسلاميات ص٥+ (٤) اسلاميات ص٦ فصلين | E9: 24
A10: محمد الغباشي | B10: لغة عربية | C10: 25 | D10: (٥) لغتي ص 4 فصل(2/4) + (١٠) لغتي ص٥ فصلين +(١٠) لغتي ص٦ فصلين | E10: 25
A11: طارق عبدالظاهر | B11: رياضيات | C11: 24 | D11: (18) رياضيات ص٤ +(6) رياضيات ص٥ فصل | E11: 24
A12: احمد سالم | B12: رياضيات | C12: 24 | D12: (١٢) رياضيات ص٦ فصلين + مسند (6) رياضيات ص5 فصل + (5) نشاط ص4 وص5 + (1) نشاط ص6 فصل | E12: 24
A13: عمرو محمد | B13: رياضيات | C13: 24 | D13: (12) رياضيات ص٢ ب فصلين+(12) رياضيات ص٣ فصلين | E13: 24
A14: ربيع عوض | B14: لغة انجليزية | C14: 24 | D14: (٦) E ص٥ + (٦) E ص٦ + (٩) E ص٤ + (2) انجليزي إثرائي ص6 + (1) نشاط ص6 فصل | E14: 24
A15: محمد السيد | B15: لغة انجليزية | C15: 24 | D15: (٦) E ص٣ + + (٤) E اثرائي ص3 + (٦) E اثرائي ص٤ + (2) E اثرائي ص٦+ (٤) E اثراىي ص٥ +(2) انجليزي اثرائي ص2 فصل | E15: 24
A16: احمد حسنين | B16: لغة انجليزية | C16: 24 | D16: (6) E ص١+ (٤) E اثرائي ص١+ (٦) E ص٢ + (2) E اثرائي ص٢ فصل+ (4) ماث ص١ + (٢) ساينس ص١ | E16: 24
... A22: آمير جلال | B22: رقمية | C22: 24 | D22: (2) رقمية ص١+ (٤) رقمية ص٢+ (٤) رقمية ص٣ + (٦) رقمية ص٤ + (٤) رقمية ص٥ + (٤) رقمية ص٦ | E22: 24
A23: إجمالي الحصص | B23: 396 | C23: =SUM(C5:C22) -> 433 | D23: اضافة عدد (٣٨) حصة اثرائي لغة انجليزية + (١٢) اثرائي رقمية صفوف أولية فيصبح مجموع الحصص الاثرائية (٥٠) حصة تخفيض (١) حصة فنية الصف الاول باجمالي (٢) حصة تخفيض (١) حصة بدنية الصف الاول باجمالي (٢) حصة تخفيض (١) حصة اسلاميات الصف الاول باجمالي (٢) حصة تخفيض (١) حصة اسلاميات صفوف عليا باجمالي (٧) حصص تخفيض حصة رقمية صف 1 استبدال (٣٢) حصة نشاط مع الحصص الاثرائية (٥٠) - (٣٢) = (١٨) حصة
A25: اسنادات متوسط دار القلم الفصل الاول 1447
A27: المعلم | B27: المادة | C27: عدد حصص المعلم بالمدرسة | D27: الإسناد | E27: إجمالي نصاب المعلم
A28: فواز المطيري | B28: اسلاميات | C28: 25 | D28: (5) اسلاميات ص1 فصل 1/1 +(10) اسلاميات ص2 فصلين 2/1 - 2/2 + (10) اسلاميات ص 3 فصل 3/1 - 3/2 | E28: 25
A29: احمد صوفي | B29: لغة عربية | C29: 26 | D29: (15) لغتي ص1 متوسط + (٥) اسلاميات ص2 فصل 2/3 +(6) تفكير ناقد متوسط ص٣ | E29: 26
A30: محمد سمير | B30: لغة عربية | C30: 27 | D30: (15) لغتي ص2 م + (12 ) لغتي ص 3 | E30: 27
A31: ماهر الحربي | B31: رياضيات | C31: 24 | D31: (18) رياضيات ص١+ (6) رياضيات ص2م فصل 2/3 | E31: 30
A32: حسن السيد | B32: رياضيات | C32: 30 | D32: (18) رياضيات ص3م + (6) رياضيات ص2م فصل 2/2 - 2/3 | E32: 24
A33: سلمان الصادق | B33: لغة انجليزية | C33: 24 | D33: (12) انجليزي ص٢متوسط +(12) انجليزي ص٣ متوسط | E33: 24
A34: مصطفى فتحي | B34: لغة انجليزية | C34: 12 | D34: (١٢) انجليزي ص١ متوسط + مكمل (١٢) حصة بالثانوي | E34: 24
A35: فارس الجندي | B35: علوم | C35: 24 | D35: (12) علوم ص١ +(12) علوم ص٢ | E35: 24
A36: محمد العشماوي | B36: علوم | C36: 27 | D36: (12) علوم ص٣ +(10) اسلاميات ص1 فصل 1/2 - 1/3 + ( 5 ) اسلاميات صف 3 فصل 3/3 | E36: 27
A37: عبدالعزيز الربيعان | B37: اجتماعيات | C37: 24 | D37: (24) اجتماعيات (9) ص١ + (9 ) ص٢ +( 6 ) ص٣ متوسط | E37: 24
A38: محمود صابر | B38: فنية | C38: 27 | D38: (18) فنية ص١ ص٢ ص٣ + (9) حياتية ص١ + ص2 + ص3 فصل | E38: 27
A39: حسين عويضة (مكمل مكرر من الثانوي) | B39: بدنية | C39: 12 | D39: ( 6) بدنية ص2 متوسط + (6) بدنية ص٣ متوسط + مكمل (١٣) حصة بالثانوي | E39: 25
... A41: محمود جمعه | B41: رقمية | C41: 25 | D41: (٦) رقمية ص١متوسط +(4) رقمية ص٢ متوسط فصل 1 + فصل 2 + ( 6) بدنية ص1 متوسط + (3) نشاط ص1 + (3) نشاط ص 3 + (3) نشاط ص2 | E41: 25
C42: =SUM(C28:C41) -> 315 | E42: =SUM(E28:E41) -> 358
A44: اسنادات ثانوية دار القلم الفصل الدراسي الأول 1447
A46: المعلم | B46: المادة | C46: عدد حصص المعلم بالمدرسة | D46: الإسناد | E46: عدد حصص المعلم بالمدرسة
A47: احمد نصر | B47: لغة عربية | C47: 24 | D47: 20 كفايات 1ث من 6:2 +4 كفايات 2ث 7 | E47: 24
A48: هشام رسمي | B48: لغة عربية | C48: 27 | D48: 24 حصة كفايات 2ث 6فصول من 6:1+ 3 حصص 2-ث نون | E48: 27
A49: حسن الخطيب | B49: لغة عربية | C49: 24 | D49: 14 مهارا ت بحث 3 ث كامل + 6 كفايات 1ث نون +4 كفايات 1ث 1 | E49: 24
A50: عبد العزيز الربيعان | B50: لغة عربية | C50: 26 | D50: 21 تاريخ 2ث كامل+2 تاريخ 2ث نون +3 تفسير 1ث2 نون | E50: 26
A51: خالد المطيري | B51: اسلاميات | C51: 27 | D51: 24 تفسير وقران 1ث كامل + 3 تفسير 1ث1 نون | E51: 27
A52: حسام السيد | B52: رياضيات | C52: 28 | D52: 20 صف2ث 4 فصول 4:1+4 نون صف2ث + 4 صف3ث1 | E52: 28
...

Sheet اسناد البنات ف١
A1: اسنادات الابتدائي
A2: المعلم | B2: المادة | C2: عدد حصص المعلم بالمرحلة | D2: ملاحظات | E2: إجمالي نصاب المعلم بعد الاكمال
A4: نورا مجدي | B4: انجليزي | C4: 24 | D4: (3) انجليزي وزاري ص1 ( 2) انجليزي اثرائي ص1 (1) ماث ص1 ( 1) ساينس ص1 ( 3) انجليزي وزاري ص2 (2) انجليزي اثرائي ص2 (6) انجليزي وزاري ص3 (4)انجليزي اثرائي ص3 (2) نشاط ص5 | E4: 24
A5: سارة المخلفي | B5: إسلامية | C5: 24 | D5: (10)اسلاميةص3(5)اسلاميةص4(5)إسلامية ص5(2)اجتماعيات ص5(2)نشاط ص4 + منسقة تطوع ابتدائي ومتوسط | E5: 24
A6: نوير الشمري ( مكرر مكمل من الثانوي) | B6: حاسب | C6: 8 | D6: (2) رقمية ص2 (2)رقمية ص4(2)رقمية ص5(2) رقمية ص6 + مسند (٦) حصص بالمتوسط + (10) حصة بالثانوي | E6: 24
